Workbook
Name a: [1]LogisticaSolver!$C$1
Name a: [2]EvolEdadesCol!$H$1
Name b: [1]LogisticaSolver!$C$3
Name b: [2]EvolEdadesCol!$H$2
Name d: [2]EvolEdadesCol!$H$4
Name e: [2]EvolEdadesCol!$H$5
Name h: [2]EvolEdadesCol!$H$3
Name Po: [1]LogisticaSolver!$C$2

Sheet Pob_Col_Ant_Amva_Med
A1: Año | B1: Pob_Colombia | C1: Pob_Antioquia | D1: Pob_Amva | E1: Pob_Medellin
A2: 1912 | B2: 5472604 | C2: 740937 | D2: 119534 | E2: 71004
A3: 1918 | B3: 5855077 | C3: 823226 | D3: 136143 | E3: 79146
A4: 1928 | B4: 7851110 | C4: 1011324 | D4: 190593 | E4: 120044
A5: 1938 | B5: 8697041 | C5: 1188587 | D5: 246025 | E5: 168266
A6: 1950 | B6: 12340899 | C6: 1682031.4 | D6: 455431.46 | E6: 326296.65
A7: 1951 | B7: 12690506 | C7: 1733323.3 | D7: 499756 | E7: 358189
A8: 1955 | B8: 14225196 | C8: 1951556.5 | D8: 680382.44 | E8: 485795.9
A9: 1960 | B9: 16480377 | C9: 2251451.6 | D9: 905333.42 | E9: 645295.15
A10: 1964 | B10: 18588719 | C10: 2510665.7 | D10: 1084660 | E10: 772887
A11: 1973 | B11: 23668841 | C11: 3145883.3 | D11: 1517944 | E11: 1093191
A12: 1975 | B12: 24757082 | C12: 3295136.3 | D12: 1634329 | E12: 1166985
A13: 1980 | B13: 27738076 | C13: 3678290.9 | D13: 1925291.5 | E13: 1351470
... A20: 2023 | B20: 52362900 | C20: 6994792 | D20: 4247875 | E20: 2653729

Sheet PobRef
A1: Año de referencia | B1: 2023
B2: =+LOOKUP($B$1,Pob_Col_Ant_Amva_Med!$A$2:$A$20,Pob_Col_Ant_Amva_Med!B2:B20) -> 52362900 | C2: =+LOOKUP($B$1,Pob_Col_Ant_Amva_Med!$A$2:$A$20,Pob_Col_Ant_Amva_Med!C2:C20) -> 6994792 | D2: =+LOOKUP($B$1,Pob_Col_Ant_Amva_Med!$A$2:$A$20,Pob_Col_Ant_Amva_Med!D2:D20) -> 4247875 | E2: =+LOOKUP($B$1,Pob_Col_Ant_Amva_Med!$A$2:$A$20,Pob_Col_Ant_Amva_Med!E2:E20) -> 2653729
A3: Año | B3: =CONCATENATE(Pob_Col_Ant_Amva_Med!B1," vs Pob año: ",$B$1) -> Pob_Colombia vs Pob año: 2023 | C3: =CONCATENATE(Pob_Col_Ant_Amva_Med!C1," vs Pob año: ",$B$1) -> Pob_Antioquia vs Pob año: 2023 | D3: =CONCATENATE(Pob_Col_Ant_Amva_Med!D1," vs Pob año: ",$B$1) -> Pob_Amva vs Pob año: 2023 | E3: =CONCATENATE(Pob_Col_Ant_Amva_Med!E1," vs Pob año: ",$B$1) -> Pob_Medellin vs Pob año: 2023
A4: =+Pob_Col_Ant_Amva_Med!A2-Pob_Col_Ant_Amva_Med!$A$2 -> 0 | B4: =+Pob_Col_Ant_Amva_Med!B2/$B$2 -> 0.104513 | C4: =+Pob_Col_Ant_Amva_Med!C2/$C$2 -> 0.10592695 | D4: =+Pob_Col_Ant_Amva_Med!D2/$D$2 -> 0.028139717 | E4: =+Pob_Col_Ant_Amva_Med!E2/$E$2 -> 0.026756312
A5: =+Pob_Col_Ant_Amva_Med!A3-Pob_Col_Ant_Amva_Med!$A$2 -> 6 | B5: =+Pob_Col_Ant_Amva_Med!B3/$B$2 -> 0.11181728 | C5: =+Pob_Col_Ant_Amva_Med!C3/$C$2 -> 0.11769128 | D5: =+Pob_Col_Ant_Amva_Med!D3/$D$2 -> 0.032049672 | E5: =+Pob_Col_Ant_Amva_Med!E3/$E$2 -> 0.029824447
A6: =+Pob_Col_Ant_Amva_Med!A4-Pob_Col_Ant_Amva_Med!$A$2 -> 16 | B6: =+Pob_Col_Ant_Amva_Med!B4/$B$2 -> 0.1499365 | C6: =+Pob_Col_Ant_Amva_Med!C4/$C$2 -> 0.14458243 | D6: =+Pob_Col_Ant_Amva_Med!D4/$D$2 -> 0.044867846 | E6: =+Pob_Col_Ant_Amva_Med!E4/$E$2 -> 0.045235968
A7: =+Pob_Col_Ant_Amva_Med!A5-Pob_Col_Ant_Amva_Med!$A$2 -> 26 | B7: =+Pob_Col_Ant_Amva_Med!B5/$B$2 -> 0.16609166 | C7: =+Pob_Col_Ant_Amva_Med!C5/$C$2 -> 0.16992457 | D7: =+Pob_Col_Ant_Amva_Med!D5/$D$2 -> 0.057917194 | E7: =+Pob_Col_Ant_Amva_Med!E5/$E$2 -> 0.063407379
A8: =+Pob_Col_Ant_Amva_Med!A6-Pob_Col_Ant_Amva_Med!$A$2 -> 38 | B8: =+Pob_Col_Ant_Amva_Med!B6/$B$2 -> 0.2356802 | C8: =+Pob_Col_Ant_Amva_Med!C6/$C$2 -> 0.2404691 | D8: =+Pob_Col_Ant_Amva_Med!D6/$D$2 -> 0.10721395 | E8: =+Pob_Col_Ant_Amva_Med!E6/$E$2 -> 0.12295779
A9: =+Pob_Col_Ant_Amva_Med!A7-Pob_Col_Ant_Amva_Med!$A$2 -> 39 | B9: =+Pob_Col_Ant_Amva_Med!B7/$B$2 -> 0.24235683 | C9: =+Pob_Col_Ant_Amva_Med!C7/$C$2 -> 0.24780198 | D9: =+Pob_Col_Ant_Amva_Med!D7/$D$2 -> 0.11764847 | E9: =+Pob_Col_Ant_Amva_Med!E7/$E$2 -> 0.13497573
A10: =+Pob_Col_Ant_Amva_Med!A8-Pob_Col_Ant_Amva_Med!$A$2 -> 43 | B10: =+Pob_Col_Ant_Amva_Med!B8/$B$2 -> 0.27166555 | C10: =+Pob_Col_Ant_Amva_Med!C8/$C$2 -> 0.27900136 | D10: =+Pob_Col_Ant_Amva_Med!D8/$D$2 -> 0.16017007 | E10: =+Pob_Col_Ant_Amva_Med!E8/$E$2 -> 0.18306161
A11: =+Pob_Col_Ant_Amva_Med!A9-Pob_Col_Ant_Amva_Med!$A$2 -> 48 | B11: =+Pob_Col_Ant_Amva_Med!B9/$B$2 -> 0.31473385 | C11: =+Pob_Col_Ant_Amva_Med!C9/$C$2 -> 0.32187542 | D11: =+Pob_Col_Ant_Amva_Med!D9/$D$2 -> 0.21312619 | E11: =+Pob_Col_Ant_Amva_Med!E9/$E$2 -> 0.24316543
A12: =+Pob_Col_Ant_Amva_Med!A10-Pob_Col_Ant_Amva_Med!$A$2 -> 52 | B12: =+Pob_Col_Ant_Amva_Med!B10/$B$2 -> 0.35499789 | C12: =+Pob_Col_Ant_Amva_Med!C10/$C$2 -> 0.35893357 | D12: =+Pob_Col_Ant_Amva_Med!D10/$D$2 -> 0.25534179 | E12: =+Pob_Col_Ant_Amva_Med!E10/$E$2 -> 0.29124564
A13: =+Pob_Col_Ant_Amva_Med!A11-Pob_Col_Ant_Amva_Med!$A$2 -> 61 | B13: =+Pob_Col_Ant_Amva_Med!B11/$B$2 -> 0.45201548 | C13: =+Pob_Col_Ant_Amva_Med!C11/$C$2 -> 0.44974652 | D13: =+Pob_Col_Ant_Amva_Med!D11/$D$2 -> 0.35734197 | E13: =+Pob_Col_Ant_Amva_Med!E11/$E$2 -> 0.41194523
A14: =+Pob_Col_Ant_Amva_Med!A12-Pob_Col_Ant_Amva_Med!$A$2 -> 63 | B14: =+Pob_Col_Ant_Amva_Med!B12/$B$2 -> 0.47279815 | C14: =+Pob_Col_Ant_Amva_Med!C12/$C$2 -> 0.47108424 | D14: =+Pob_Col_Ant_Amva_Med!D12/$D$2 -> 0.38474037 | E14: =+Pob_Col_Ant_Amva_Med!E12/$E$2 -> 0.43975289
A15: =+Pob_Col_Ant_Amva_Med!A13-Pob_Col_Ant_Amva_Med!$A$2 -> 68 | B15: =+Pob_Col_Ant_Amva_Med!B13/$B$2 -> 0.52972765 | C15: =+Pob_Col_Ant_Amva_Med!C13/$C$2 -> 0.52586137 | D15: =+Pob_Col_Ant_Amva_Med!D13/$D$2 -> 0.45323638 | E15: =+Pob_Col_Ant_Amva_Med!E13/$E$2 -> 0.50927205
... A22: =+Pob_Col_Ant_Amva_Med!A20-Pob_Col_Ant_Amva_Med!$A$2 -> 111 | B22: =+Pob_Col_Ant_Amva_Med!B20/$B$2 -> 1 | C22: =+Pob_Col_Ant_Amva_Med!C20/$C$2 -> 1 | D22: =+Pob_Col_Ant_Amva_Med!D20/$D$2 -> 1 | E22: =+Pob_Col_Ant_Amva_Med!E20/$E$2 -> 1

Sheet Pob_World_LATAM_Col
A1: Notes
A2: Country code | B2: 900 | C2: 931 | D2: 170
A3: Type | B3: World | C3: Subregion | D3: Country/Area
A4: Parent code | B4: 0 | C4: 1830 | D4: 931
A5: Region, subregion, country or area * | B5: WORLD | C5: South America | D5: Colombia
A6: 1950 | B6: 2536431 | C6: 113765.19 | D6: 11981.576
A7: 1951 | B7: 2584034.2 | C7: 116853.65 | D7: 12295.965
A8: 1952 | B8: 2630861.7 | C8: 120043.21 | D8: 12633.899
A9: 1953 | B9: 2677609.1 | C9: 123321.74 | D9: 12993.849
A10: 1954 | B10: 2724846.8 | C10: 126681.75 | D10: 13374.543
A11: 1955 | B11: 2773019.9 | C11: 130120.24 | D11: 13774.999
A12: 1956 | B12: 2822443.3 | C12: 133638.91 | D12: 14194.561
A13: 1957 | B13: 2873306.1 | C13: 137244.22 | D13: 14632.794
A14: 1958 | B14: 2925686.7 | C14: 140946.13 | D14: 15089.522
A15: 1959 | B15: 2979576.1 | C15: 144756.68 | D15: 15564.624
A16: 1960 | B16: 3034949.7 | C16: 148685.68 | D16: 16057.714
A17: 1961 | B17: 3091843.5 | C17: 152735.9 | D17: 16567.817
... A157: 2100 | B157: 10875394 | C157: 429300.72 | D157: 45221.276

Sheet Evolucion edades
A1: Años | B1: 0-19 | C1: 20-64 | D1: > 65 | E1: Total
A2: 1960 | B2: 35.4 | C2: 56.4 | D2: 8.2 | E2: 100
A3: 1970 | B3: 35.7 | C3: 54.5 | D3: 9.8 | E3: 100
A4: 1981 | B4: 34.4 | C4: 54.4 | D4: 11.2 | E4: 100
A5: 1991 | B5: 28 | C5: 58.2 | D5: 13.8 | E5: 100
A6: 1995 | B6: 24 | C6: 60.7 | D6: 15.3 | E6: 100
A7: 2000 | B7: 20.8 | C7: 62.4 | D7: 16.9 | E7: 100
A8: 2005 | B8: 19.1 | C8: 63.5 | D8: 17.4 | E8: 100
A9: 2010 | B9: 18.1 | C9: 63.8 | D9: 18.1 | E9: 100
A10: 2015 | B10: 17 | C10: 63.7 | D10: 19.3 | E10: 100
A11: 2020 | B11: 15.9 | C11: 63.5 | D11: 20.6 | E11: 100
A41: Rango edad | B41: edad media | C41: 1960 | D41: 1965 | E41: 1970 | F41: 1975 | G41: 1980 | H41: 1985 | I41: Final | J41: Poblacion
A42: 0-4 | B42: 2 | C42: 9.46 | D42: 9.46 | E42: 9.47 | F42: 9.47 | G42: 9.46 | H42: 9.44 | I42: 9.48 | J42: 7165646
A43: 5-9 | B43: 7 | C43: 9.01 | D43: 8.96 | E43: 8.98 | F43: 8.99 | G43: 9 | H43: 8.99 | I43: 8.98 | J43: 6824434
A44: 10-14 | B44: 12 | C44: 8.71 | D44: 8.65 | E44: 8.62 | F44: 8.74 | G44: 8.67 | H44: 8.67 | I44: 8.64 | J44: 6583237
A45: 15-19 | B45: 17 | C45: 8.41 | D45: 8.34 | E45: 8.29 | F45: 8.28 | G45: 8.3 | H45: 8.33 | I45: 8.3 | J45: 6319177
A46: 20-24 | B46: 22 | C46: 8.01 | D46: 7.99 | E46: 7.94 | F46: 7.88 | G46: 7.88 | H46: 7.9 | I46: 7.91 | J46: 5994555
A47: 25-29 | B47: 27 | C47: 7.48 | D47: 7.54 | E47: 7.53 | F47: 7.48 | G47: 7.44 | H47: 7.44 | I47: 7.47 | J47: 5644290
A48: 30-34 | B48: 32 | C48: 6.94 | D48: 7.01 | E48: 7.08 | F48: 7.07 | G48: 7.04 | H48: 7 | I48: 7.03 | J48: 5313738
A49: 35-39 | B49: 37 | C49: 6.47 | D49: 6.5 | E49: 6.58 | F49: 6.64 | G49: 6.65 | H49: 6.61 | I49: 6.59 | J49: 5016417
A50: 40-44 | B50: 42 | C50: 6.34 | D50: 6.06 | E50: 6.1 | F50: 6.17 | G50: 6.24 | H50: 6.24 | I50: 6.16 | J50: 4734655
A51: 45-49 | B51: 47 | C51: 6.07 | D51: 5.9 | E51: 5.64 | F51: 5.68 | G51: 5.76 | H51: 5.82 | I51: 5.74 | J51: 4416970
A52: 50-54 | B52: 52 | C52: 5.4 | D52: 5.58 | E52: 5.43 | F52: 5.19 | G52: 5.24 | H52: 5.31 | I52: 5.3 | J52: 4028779
A53: 55-59 | B53: 57 | C53: 4.57 | D53: 4.86 | E53: 5.03 | F53: 4.9 | G53: 4.69 | H53: 4.73 | I53: 4.79 | J53: 3587295
... A61: 95-99 | B61: 97 | C61: 0.01 | D61: 0.01 | E61: 0.01 | F61: 0.01 | G61: 0.01 | H61: 0.01 | I61: 0.04 | J61: 10129
A62: >100 | B62: 102 | I62: 0.01 | J62: 694
C63: =SUM(C42:C62) -> 99.96 | D63: =SUM(D42:D62) -> 99.93 | E63: =SUM(E42:E62) -> 99.96 | F63: =SUM(F42:F62) -> 100.02 | G63: =SUM(G42:G62) -> 100.02 | H63: =SUM(H42:H62) -> 100 | I63: =SUM(I42:I62) -> 100 | J63: =SUM(J42:J62) -> 75901902
A65: Rango edad | B65: 0-4 | C65: 5-9 | D65: 10-14 | E65: 15-19 | F65: 20-24 | G65: 25-29 | H65: 30-34 | I65: 35-39 | J65: 40-44 | K65: 45-49 | L65: 50-54 | M65: 55-59 | N65: 60-64 | O65: 65-69 | P65: 70-74 | Q65: 75-79 | R65: 80-84 | S65: 85-89 | T65: 90-94 | U65: 95-99 | V65: >100
A66: edad media | B66: 2 | C66: 7 | D66: 12 | E66: 17 | F66: 22 | G66: 27 | H66: 32 | I66: 37 | J66: 42 | K66: 47 | L66: 52 | M66: 57 | N66: 62 | O66: 67 | P66: 72 | Q66: 77 | R66: 82 | S66: 87 | T66: 92 | U66: 97 | V66: 102
A67: 0 | B67: 9.46 | C67: 9.01 | D67: 8.71 | E67: 8.41 | F67: 8.01 | G67: 7.48 | H67: 6.94 | I67: 6.47 | J67: 6.34 | K67: 6.07 | L67: 5.4 | M67: 4.57 | N67: 4.19 | O67: 3.56 | P67: 2.52 | Q67: 1.65 | R67: 0.79 | S67: 0.3 | T67: 0.07 | U67: 0.01
A68: 5 | B68: 9.46 | C68: 8.96 | D68: 8.65 | E68: 8.34 | F68: 7.99 | G68: 7.54 | H68: 7.01 | I68: 6.5 | J68: 6.06 | K68: 5.9 | L68: 5.58 | M68: 4.86 | N68: 3.98 | O68: 3.46 | P68: 2.68 | Q68: 1.67 | R68: 0.89 | S68: 0.32 | T68: 0.07 | U68: 0.01
A69: 10 | B69: 9.47 | C69: 8.98 | D69: 8.62 | E69: 8.29 | F69: 7.94 | G69: 7.53 | H69: 7.08 | I69: 6.58 | J69: 6.1 | K69: 5.64 | L69: 5.43 | M69: 5.03 | N69: 4.24 | O69: 3.29 | P69: 2.61 | Q69: 1.78 | R69: 0.89 | S69: 0.36 | T69: 0.09 | U69: 0.01
A70: 15 | B70: 9.47 | C70: 8.99 | D70: 8.74 | E70: 8.28 | F70: 7.88 | G70: 7.48 | H70: 7.07 | I70: 6.64 | J70: 6.17 | K70: 5.68 | L70: 5.19 | M70: 4.9 | N70: 4.39 | O70: 3.51 | P70: 2.48 | Q70: 1.73 | R70: 0.95 | S70: 0.36 | T70: 0.1 | U70: 0.01
A71: 20 | B71: 9.46 | C71: 9 | D71: 8.67 | E71: 8.3 | F71: 7.88 | G71: 7.44 | H71: 7.04 | I71: 6.65 | J71: 6.24 | K71: 5.76 | L71: 5.24 | M71: 4.69 | N71: 4.28 | O71: 3.64 | P71: 2.65 | Q71: 1.65 | R71: 0.93 | S71: 0.39 | T71: 0.1 | U71: 0.01
A72: 25 | B72: 9.44 | C72: 8.99 | D72: 8.67 | E72: 8.33 | F72: 7.9 | G72: 7.44 | H72: 7 | I72: 6.61 | J72: 6.24 | K72: 5.82 | L72: 5.31 | M72: 4.73 | N72: 4.1 | O72: 3.54 | P72: 2.75 | Q72: 1.76 | R72: 0.89 | S72: 0.37 | T72: 0.1 | U72: 0.01
A73: Final | B73: 9.48 | C73: 8.98 | D73: 8.64 | E73: 8.31 | F73: 7.91 | G73: 7.47 | H73: 7.03 | I73: 6.59 | J73: 6.16 | K73: 5.74 | L73: 5.3 | M73: 4.79 | N73: 4.19 | O73: 3.5 | P73: 2.64 | Q73: 1.76 | R73: 0.95 | S73: 0.41 | T73: 0.11 | U73: 0.04 | V73: 0.01
A74: Poblacion | B74: 7165646 | C74: 6824434 | D74: 6583237 | E74: 6319177 | F74: 5994555 | G74: 5644290 | H74: 5313738 | I74: 5016417 | J74: 4734655 | K74: 4416970 | L74: 4028779 | M74: 3587295 | N74: 3112638 | O74: 2690630 | P74: 2088417 | Q74: 1334255 | R74: 672759 | S74: 284612 | T74: 78575 | U74: 10129 | V74: 694

Sheet LogisticaCol
C1: a | D1: -55.688827 | G1: -55.651132 | H1: -4.6135941 | I1: -4.7769089 | J1: -2.9086224
C2: b | D2: -3.4760113 | G2: -3.4788009 | H2: -4.0016108 | I2: -3.9146793 | J2: -3.8809674
C3: c | D3: 0.047011628 | G3: 0.047057895 | H3: 0.053630356 | I3: 0.05163087 | J3: 0.055008133
C4: d | D4: 59.490996 | F4: =SUM(F6:F26) -> 0.74011409 | G4: 59.462105 | H4: 4.5962634 | I4: 4.7409135 | J4: 2.8822749
A5: Año | B5: Año | C5: 1. Pob_Col | D5: Pob est | E5: P - Pest. | F5: SSD | G5: 1. Pob_Col | H5: 2. Pob_Ant | I5: 3. Pob_Amva | J5: 4. Pob_Med
A6: 1912 | B6: 0 | C6: =+LOOKUP($C$5,$G$5:$J$5,G6:J6)/1000000 -> 5.472604 | D6: =$D$4+($D$1/(1+EXP($D$2+$D$3*B6))) -> 5.4729753 | E6: =C6-D6 -> -0.00037126674 | F6: =E6*E6 -> 1.3783899e-07 | G6: 5472604 | H6: 740937 | I6: 119534 | J6: 71004
A7: =+$A$6+B7 -> 1918 | B7: 6 | C7: =+LOOKUP($C$5,$G$5:$J$5,G7:J7)/1000000 -> 5.855077 | D7: =$D$4+($D$1/(1+EXP($D$2+$D$3*B7))) -> 5.9959941 | E7: =C7-D7 -> -0.14091705 | F7: =E7*E7 -> 0.019857615 | G7: 5855077 | H7: 823226 | I7: 136143 | J7: 79146
A8: =+$A$6+B8 -> 1928 | B8: 16 | C8: =+LOOKUP($C$5,$G$5:$J$5,G8:J8)/1000000 -> 7.85111 | D8: =$D$4+($D$1/(1+EXP($D$2+$D$3*B8))) -> 7.2316002 | E8: =C8-D8 -> 0.61950985 | F8: =E8*E8 -> 0.38379245 | G8: 7851110 | H8: 1011324 | I8: 190593 | J8: 120044
A9: =+$A$6+B9 -> 1938 | B9: 26 | C9: =+LOOKUP($C$5,$G$5:$J$5,G9:J9)/1000000 -> 8.697041 | D9: =$D$4+($D$1/(1+EXP($D$2+$D$3*B9))) -> 9.094279 | E9: =C9-D9 -> -0.39723803 | F9: =E9*E9 -> 0.15779805 | G9: 8697041 | H9: 1188587 | I9: 246025 | J9: 168266
A10: =+$A$6+B10 -> 1950 | B10: 38 | C10: =+LOOKUP($C$5,$G$5:$J$5,G10:J10)/1000000 -> 12.340899 | D10: =$D$4+($D$1/(1+EXP($D$2+$D$3*B10))) -> 12.480297 | E10: =C10-D10 -> -0.13939751 | F10: =E10*E10 -> 0.019431665 | G10: 12340899 | H10: 1682031.4 | I10: 455431.46 | J10: 326296.65
A11: =+$A$6+B11 -> 1951 | B11: 39 | C11: =+LOOKUP($C$5,$G$5:$J$5,G11:J11)/1000000 -> 12.690506 | D11: =$D$4+($D$1/(1+EXP($D$2+$D$3*B11))) -> 12.830292 | E11: =C11-D11 -> -0.13978642 | F11: =E11*E11 -> 0.019540244 | G11: 12690506 | H11: 1733323.3 | I11: 499756 | J11: 358189
A12: =+$A$6+B12 -> 1955 | B12: 43 | C12: =+LOOKUP($C$5,$G$5:$J$5,G12:J12)/1000000 -> 14.225196 | D12: =$D$4+($D$1/(1+EXP($D$2+$D$3*B12))) -> 14.344523 | E12: =C12-D12 -> -0.11932702 | F12: =E12*E12 -> 0.014238937 | G12: 14225196 | H12: 1951556.5 | I12: 680382.44 | J12: 485795.9
A13: =+$A$6+B13 -> 1960 | B13: 48 | C13: =+LOOKUP($C$5,$G$5:$J$5,G13:J13)/1000000 -> 16.480377 | D13: =$D$4+($D$1/(1+EXP($D$2+$D$3*B13))) -> 16.501043 | E13: =C13-D13 -> -0.020665541 | F13: =E13*E13 -> 0.00042706458 | G13: 16480377 | H13: 2251451.6 | I13: 905333.42 | J13: 645295.15
A14: =+$A$6+B14 -> 1964 | B14: 52 | C14: =+LOOKUP($C$5,$G$5:$J$5,G14:J14)/1000000 -> 18.588718 | D14: =$D$4+($D$1/(1+EXP($D$2+$D$3*B14))) -> 18.437833 | E14: =C14-D14 -> 0.1508855 | F14: =E14*E14 -> 0.022766433 | G14: 18588718 | H14: 2510665.7 | I14: 1084660 | J14: 772887
A15: =+$A$6+B15 -> 1973 | B15: 61 | C15: =+LOOKUP($C$5,$G$5:$J$5,G15:J15)/1000000 -> 23.668841 | D15: =$D$4+($D$1/(1+EXP($D$2+$D$3*B15))) -> 23.429509 | E15: =C15-D15 -> 0.2393323 | F15: =E15*E15 -> 0.05727995 | G15: 23668841 | H15: 3145883.3 | I15: 1517944 | J15: 1093191
A16: =+$A$6+B16 -> 1975 | B16: 63 | C16: =+LOOKUP($C$5,$G$5:$J$5,G16:J16)/1000000 -> 24.757082 | D16: =$D$4+($D$1/(1+EXP($D$2+$D$3*B16))) -> 24.640428 | E16: =C16-D16 -> 0.11665354 | F16: =E16*E16 -> 0.01360805 | G16: 24757082 | H16: 3295136.3 | I16: 1634329 | J16: 1166985
A17: =+$A$6+B17 -> 1980 | B17: 68 | C17: =+LOOKUP($C$5,$G$5:$J$5,G17:J17)/1000000 -> 27.738076 | D17: =$D$4+($D$1/(1+EXP($D$2+$D$3*B17))) -> 27.784277 | E17: =C17-D17 -> -0.046200657 | F17: =E17*E17 -> 0.0021345007 | G17: 27738076 | H17: 3678290.9 | I17: 1925291.5 | J17: 1351470
A18: =+$A$6+B18 -> 1985 | B18: 73 | C18: =+LOOKUP($C$5,$G$5:$J$5,G18:J18)/1000000 -> 31.011862 | D18: =$D$4+($D$1/(1+EXP($D$2+$D$3*B18))) -> 31.031844 | E18: =C18-D18 -> -0.019981703 | F18: =E18*E18 -> 0.00039926847 | G18: 31011862 | H18: 4072705.3 | I18: 2216254 | J18: 1535955
... A31: =+$A$6+B31 -> 2050 | B31: 138 | C31: =+LOOKUP($C$5,$G$5:$J$5,G31:J31)/1000000 -> 55.267358 | D31: =$D$4+($D$1/(1+EXP($D$2+$D$3*B31))) -> 56.878919 | E31: =C31-D31 -> -1.611561 | F31: =E31*E31 -> 2.5971288 | G31: 55267358 | H31: 8292722.5 | I31: 4862742.3 | J31: 2790117.8
A32: =+$A$6+B32 -> 2060 | B32: 148 | D32: =$D$4+($D$1/(1+EXP($D$2+$D$3*B32))) -> 57.8294
A33: =+$A$6+B33 -> 2070 | B33: 158 | D33: =$D$4+($D$1/(1+EXP($D$2+$D$3*B33))) -> 58.440863
A34: =+$A$6+B34 -> 2080 | B34: 168 | D34: =$D$4+($D$1/(1+EXP($D$2+$D$3*B34))) -> 58.830062

Sheet Veredas_Antioquia
A1: Id-Vereda_Mpio | B1: Municipio | C1: Vereda | D1: Extension_Ha | E1: Poblacion_hab | F1: CAR
A2: Altamira-ABEJORRAL | B2: ABEJORRAL | C2: Altamira | D2: 213.4239 | E2: 201
A3: Alto Bonito-ABEJORRAL | B3: ABEJORRAL | C3: Alto Bonito | D3: 177.86724
A4: Alto de Letras-ABEJORRAL | B4: ABEJORRAL | C4: Alto de Letras | D4: 262.48794
A5: Aures Arriba-ABEJORRAL | B5: ABEJORRAL | C5: Aures Arriba | D5: 2050.1715 | E5: 291
A6: Aures El Silencio-ABEJORRAL | B6: ABEJORRAL | C6: Aures El Silencio | D6: 596.06733
A7: Cañaveral-ABEJORRAL | B7: ABEJORRAL | C7: Cañaveral | D7: 751.10104 | E7: 224
A8: Carrizales-ABEJORRAL | B8: ABEJORRAL | C8: Carrizales | D8: 886.62467 | E8: 190
A9: Chagualal-ABEJORRAL | B9: ABEJORRAL | C9: Chagualal | D9: 976.95254 | E9: 747
A10: Combia-ABEJORRAL | B10: ABEJORRAL | C10: Combia | D10: 343.40993 | E10: 59
A11: Corinto-ABEJORRAL | B11: ABEJORRAL | C11: Corinto | D11: 692.62823 | E11: 270
A12: El Buey-ABEJORRAL | B12: ABEJORRAL | C12: El Buey | D12: 748.56666 | E12: 154
A13: El Buey - Colmenas-ABEJORRAL | B13: ABEJORRAL | C13: El Buey - Colmenas | D13: 1079.9731 | E13: 74
A14: El Carmelo-ABEJORRAL | B14: ABEJORRAL | C14: El Carmelo | D14: 304.55045 | E14: 161
A15: El Caunzal-ABEJORRAL | B15: ABEJORRAL | C15: El Caunzal | D15: 50.88224
A16: El Chagualo-ABEJORRAL | B16: ABEJORRAL | C16: El Chagualo | D16: 947.20216 | E16: 109
A17: El Erizo-ABEJORRAL | B17: ABEJORRAL | C17: El Erizo | D17: 1450.8942 | E17: 382
A18: El Granadillo-ABEJORRAL | B18: ABEJORRAL | C18: El Granadillo | D18: 580.2924 | E18: 211
A19: El Guaico-ABEJORRAL | B19: ABEJORRAL | C19: El Guaico | D19: 1039.524 | E19: 500
A20: El Morrón-ABEJORRAL | B20: ABEJORRAL | C20: El Morrón | D20: 422.83661 | E20: 163
A21: El Vesubio-ABEJORRAL | B21: ABEJORRAL | C21: El Vesubio | D21: 1234.5534 | E21: 352
A22: El Volcán-ABEJORRAL | B22: ABEJORRAL | C22: El Volcán | D22: 394.84759 | E22: 228
A23: Guayabal-ABEJORRAL | B23: ABEJORRAL | C23: Guayabal | D23: 1849.4583 | E23: 236
A24: Guayaquil-ABEJORRAL | B24: ABEJORRAL | C24: Guayaquil | D24: 827.2013 | E24: 126
A25: La Albania-ABEJORRAL | B25: ABEJORRAL | C25: La Albania | E25: 153
A26: La Betulia-ABEJORRAL | B26: ABEJORRAL | C26: La Betulia | D26: 408.90402 | E26: 233
A27: La Cascada-ABEJORRAL | B27: ABEJORRAL | C27: La Cascada | D27: 838.98048 | E27: 258
A28: La Circita-ABEJORRAL | B28: ABEJORRAL | C28: La Circita | D28: 563.54036 | E28: 140
A29: La Cordillera-ABEJORRAL | B29: ABEJORRAL | C29: La Cordillera | D29: 1077.5774 | E29: 130
A30: La Esperanza-ABEJORRAL | B30: ABEJORRAL | C30: La Esperanza | D30: 508.05192 | E30: 244
A31: La Florida-ABEJORRAL | B31: ABEJORRAL | C31: La Florida | D31: 273.15561 | E31: 204
A32: La Labor-ABEJORRAL | B32: ABEJORRAL | C32: La Labor | D32: 2144.3055 | E32: 263
A33: La Loma-ABEJORRAL | B33: ABEJORRAL | C33: La Loma | D33: 514.03982 | E33: 383
A34: La Loma Parte Baja-ABEJORRAL | B34: ABEJORRAL | C34: La Loma Parte Baja | D34: 521.83528
A35: La Nubia-ABEJORRAL | B35: ABEJORRAL | C35: La Nubia | D35: 217.14993
A36: La Peña-ABEJORRAL | B36: ABEJORRAL | C36: La Peña | D36: 552.94947 | E36: 362
A37: La Perdida-ABEJORRAL | B37: ABEJORRAL | C37: La Perdida | D37: 622.53799 | E37: 322
A38: La Polka-ABEJORRAL | B38: ABEJORRAL | C38: La Polka | D38: 481.93073 | E38: 261
A39: La Primavera-ABEJORRAL | B39: ABEJORRAL | C39: La Primavera | D39: 332.63971
A40: La Saltadera-ABEJORRAL | B40: ABEJORRAL | C40: La Saltadera | D40: 553.58571 | E40: 80
...

Sheet Func_de_Crecim
A1: Po | B1: 1000 | C1: =+$B$1 -> 1000 | D1: =+$B$1 -> 1000 | E1: =+$B$1 -> 1000 | F1: =+$B$1 -> 1000 | G1: =+$B$1 -> 1000 | H1: =+$B$1 -> 1000
A2: K | B2: =1/B3 -> 0.083333333 | C2: =+$B$2 -> 0.083333333 | D2: =+$B$2 -> 0.083333333 | E2: =+$B$2 -> 0.083333333 | F2: =+$B$2 -> 0.083333333 | G2: =+$B$2 -> 0.083333333 | H2: =+$B$2 -> 0.083333333
A3: k* | B3: 12
A4: Pmax | B4: 4 | H4: =+$B$4 -> 4 | I4: 30 | L4: 30 | M4: 15
A5: to | B5: 0 | C5: =+$B$5 -> 0 | D5: =+$B$5 -> 0 | E5: =+$B$5 -> 0 | F5: =+$B$5 -> 0 | H5: =+$B$5 -> 0 | L5: 20 | M5: 8
A6: Delta t | B6: 1 | C6: =+$B$6 -> 1 | D6: =+$B$6 -> 1 | E6: =+$B$6 -> 1 | F6: =+$B$6 -> 1 | H6: =+$B$6 -> 1
B7: 5 | C7: 1 | D7: 2 | E7: 3 | F7: 4 | G7: 5 | H7: 6 | I7: 7 | J7: 8 | K7: 9 | L7: 10 | M7: 11
A8: Nombre Función | B8: =+LOOKUP(B7,$C$7:$M$7,$C$8:$M$8) -> Poblacion con Nac Sal I + E | C8: Exponencial | D8: Sigmoide creciente | E8: Sigmoide decreciente | F8: Tangente hiperbolica (Bronceado) | G8: Poblacion con Nac Sal I + E | H8: Poblacion con limite | I8: Nacimientos | J8: Salidas | K8: Neto | L8: Inmigracion | M8: Emigracion
A9: t | C9: ft = Po * (1+ekt) | D9: ft = 2Po/(1+e-kt) | E9: ft = 2Po/(1+ekt) | F9: ft = Po*(1+ (ekt - e-kt) / (ekt + e-kt)) | G9: Po + Nac + I - Sal - E | H9: PmaxPoekt/(Pmax+ Po(ert-1)) | I9: (Fn/1000)*P | J9: (Fm/1000)*P | K9: Nac - Sal | L9: I | M9: E
A10: =+D5 -> 0 | B10: =+LOOKUP($B$7,$C$7:$M$7,C10:M10) -> 1000 | C10: 1000 | D10: 1000 | E10: 1000 | F10: 1000 | G10: 1000 | H10: 1000 | I10: 30 | J10: 10.002666 | K10: 19.997334 | L10: =IF(A10=$L$5,B10*($L$4/100),0) -> 0 | M10: =IF(A10=$M$5,B10*($M$4/100),0) -> 0
A11: =+A10+$D$6 -> 1 | B11: =+LOOKUP($B$7,$C$7:$M$7,C11:M11) -> 1039.9787 | C11: 1086.904 | D11: 1041.6426 | E11: 958.35743 | F11: 1083.141 | G11: 1039.9787 | H11: 1063.7921 | I11: 30.59992 | J11: 10.618573 | K11: 19.981347 | L11: =IF(A11=$L$5,B11*($L$4/100),0) -> 0 | M11: =IF(A11=$M$5,B11*($M$4/100),0) -> 0
A12: =+A11+$D$6 -> 2 | B12: =+LOOKUP($B$7,$C$7:$M$7,C12:M12) -> 1039.9787 | C12: 1181.3604 | D12: 1083.141 | E12: 916.85903 | F12: 1165.1404 | G12: 1039.9787 | H12: 1130.1206 | I12: 31.19936 | J12: 11.249937 | K12: 19.949423 | L12: =IF(A12=$L$5,B12*($L$4/100),0) -> 0 | M12: =IF(A12=$M$5,B12*($M$4/100),0) -> 0
A13: =+A12+$D$6 -> 3 | B13: =+LOOKUP($B$7,$C$7:$M$7,C13:M13) -> 1039.9787 | C13: 1284.0254 | D13: 1124.353 | E13: 875.647 | F13: 1244.9187 | G13: 1039.9787 | H13: 1198.8962 | I13: 31.797843 | J13: 11.896178 | K13: 19.901666 | L13: =IF(A13=$L$5,B13*($L$4/100),0) -> 0 | M13: =IF(A13=$M$5,B13*($M$4/100),0) -> 0
A14: =+A13+$D$6 -> 4 | B14: =+LOOKUP($B$7,$C$7:$M$7,C14:M14) -> 1039.9787 | C14: 1395.6124 | D14: 1165.1404 | E14: 834.85959 | F14: 1321.5127 | G14: 1039.9787 | H14: 1270.005 | I14: 32.394893 | J14: 12.556668 | K14: 19.838226 | L14: =IF(A14=$L$5,B14*($L$4/100),0) -> 0 | M14: =IF(A14=$M$5,B14*($M$4/100),0) -> 0
A15: =+A14+$D$6 -> 5 | B15: =+LOOKUP($B$7,$C$7:$M$7,C15:M15) -> 1039.9787 | C15: 1516.8968 | D15: 1205.3707 | E15: 794.62932 | F15: 1394.1186 | G15: 1039.9787 | H15: 1343.3088 | I15: 32.99004 | J15: 13.230736 | K15: 19.759304 | L15: =IF(A15=$L$5,B15*($L$4/100),0) -> 0 | M15: =IF(A15=$M$5,B15*($M$4/100),0) -> 0
A16: =+A15+$D$6 -> 6 | B16: =+LOOKUP($B$7,$C$7:$M$7,C16:M16) -> 1039.9787 | C16: 1648.7213 | D16: 1244.9187 | E16: 755.08134 | F16: 1462.1172 | G16: 1039.9787 | H16: 1418.645 | I16: 33.582819 | J16: 13.91767 | K16: 19.665149 | L16: =IF(A16=$L$5,B16*($L$4/100),0) -> 0 | M16: =IF(A16=$M$5,B16*($M$4/100),0) -> 0
A17: =+A16+$D$6 -> 7 | B17: =+LOOKUP($B$7,$C$7:$M$7,C17:M17) -> 1039.9787 | C17: 1792.0018 | D17: 1283.6681 | E17: 716.33191 | F17: 1525.0839 | G17: 1039.9787 | H17: 1495.8273 | I17: 34.172773 | J17: 14.616717 | K17: 19.556056 | L17: =IF(A17=$L$5,B17*($L$4/100),0) -> 0 | M17: =IF(A17=$M$5,B17*($M$4/100),0) -> 0
A18: =+A17+$D$6 -> 8 | B18: =+LOOKUP($B$7,$C$7:$M$7,C18:M18) -> 1039.9787 | C18: 1947.734 | D18: 1321.5127 | E18: 678.48726 | F18: 1582.7829 | G18: 1039.9787 | H18: 1574.6473 | I18: 34.759455 | J18: 15.327091 | K18: 19.432364 | L18: =IF(A18=$L$5,B18*($L$4/100),0) -> 0 | M18: =IF(A18=$M$5,B18*($M$4/100),0) -> 155.9968
A19: =+A18+$D$6 -> 9 | B19: =+LOOKUP($B$7,$C$7:$M$7,C19:M19) -> 1039.9787 | C19: 2117 | D19: 1358.3574 | E19: 641.6426 | F19: 1635.149 | G19: 1039.9787 | H19: 1654.8759 | I19: 35.342426 | J19: 16.047974 | K19: 19.294452 | L19: =IF(A19=$L$5,B19*($L$4/100),0) -> 0 | M19: =IF(A19=$M$5,B19*($M$4/100),0) -> 0
A20: =+A19+$D$6 -> 10 | B20: =+LOOKUP($B$7,$C$7:$M$7,C20:M20) -> 1039.9787 | C20: 2300.9759 | D20: 1394.1186 | E20: 605.88143 | F20: 1682.2618 | G20: 1039.9787 | H20: 1736.2659 | I20: 35.92126 | J20: 16.778518 | K20: 19.142741 | L20: =IF(A20=$L$5,B20*($L$4/100),0) -> 0 | M20: =IF(A20=$M$5,B20*($M$4/100),0) -> 0
A21: =+A20+$D$6 -> 11 | B21: =+LOOKUP($B$7,$C$7:$M$7,C21:M21) -> 1039.9787 | C21: 2500.94 | D21: 1428.7249 | E21: 571.27514 | F21: 1724.3167 | G21: 1039.9787 | H21: 1818.5547 | I21: 36.495542 | J21: 17.517854 | K21: 18.977688 | L21: =IF(A21=$L$5,B21*($L$4/100),0) -> 0 | M21: =IF(A21=$M$5,B21*($M$4/100),0) -> 0
A22: =+A21+$D$6 -> 12 | B22: =+LOOKUP($B$7,$C$7:$M$7,C22:M22) -> 1039.9787 | C22: 2718.2818 | D22: 1462.1172 | E22: 537.88284 | F22: 1761.5942 | G22: 1039.9787 | H22: 1901.4675 | I22: 37.064872 | J22: 18.265089 | K22: 18.799783 | L22: =IF(A22=$L$5,B22*($L$4/100),0) -> 0 | M22: =IF(A22=$M$5,B22*($M$4/100),0) -> 0
... A49: =+A48+$D$6 -> 39 | B49: =+LOOKUP($B$7,$C$7:$M$7,C49:M49) -> 1039.9787 | C49: 25790.34 | D49: 1925.3462 | E49: 74.653775 | F49: 1996.9976 | G49: 1039.9787 | H49: 3583.1935 | I49: 49.581201 | J49: 38.251137 | K49: 11.330064 | L49: =IF(A49=$L$5,B49*($L$4/100),0) -> 0 | M49: =IF(A49=$M$5,B49*($M$4/100),0) -> 0
A50: =+A49+$D$6 -> 40 | B50: =+LOOKUP($B$7,$C$7:$M$7,C50:M50) -> 1039.9787 | C50: 28031.625 | D50: 1931.1096 | E50: 68.890391 | F50: 1997.458 | G50: 1039.9787 | H50: 3613.2977 | I50: 49.921103 | L50: =IF(A50=$L$5,B50*($L$4/100),0) -> 0 | M50: =IF(A50=$M$5,B50*($M$4/100),0) -> 0

Sheet PobCol1912_2100
A1: Año | B1: Edad | C1: Male | D1: Female | E1: Total
A2: 1952 | B2: 0 | C2: 262053 | D2: 253156 | E2: 515209
A3: 1952 | B3: 1 | C3: 239019 | D3: 231988 | E3: 471007
A4: 1952 | B4: 2 | C4: 224542 | D4: 218722 | E4: 443264
A5: 1952 | B5: 3 | C5: 204940 | D5: 203131 | E5: 408071
A6: 1952 | B6: 4 | C6: 197631 | D6: 195699 | E6: 393330
A7: 1952 | B7: 5 | C7: 189157 | D7: 187430 | E7: 376587
A8: 1952 | B8: 6 | C8: 181077 | D8: 179603 | E8: 360680
A9: 1952 | B9: 7 | C9: 173655 | D9: 172440 | E9: 346095
A10: 1952 | B10: 8 | C10: 166804 | D10: 165839 | E10: 332643
A11: 1952 | B11: 9 | C11: 160426 | D11: 159705 | E11: 320131
A12: 1952 | B12: 10 | C12: 154626 | D12: 154080 | E12: 308706
A13: 1952 | B13: 11 | C13: 149347 | D13: 148917 | E13: 298264
... A4142: 2100 | B4142: 100 | C4142: 48837 | D4142: 126342 | E4142: 175179
